Workbook

Sheet DASHBOARD
A1: SSC STUDY TRACKER DASHBOARD | R1: Date | T1: Score
R2: =EOMONTH(TODAY(),-1)+1 -> 46266 | T2: 45
R3: =R2+5 -> 46271 | T3: 55 | Y3: TEST SCORES
A4: 📊 Overall Progress | D4: 📅 Study Days | G4: 📝 Total Mocks | R4: =R3+5 -> 46276 | T4: 66
A5: =E13 -> 0 | D5: 30 days | G5: 7 test per month | R5: =R4+5 -> 46281 | T5: 66
R6: =R5+5 -> 46286 | T6: 77
A7: TOTAL NO. OF TOPICS IN:- | C7: COMPLETED | D7: Pending | E7: Progress % | R7: =R6+5 -> 46291 | T7: 88
A8: MATHS | B8: =Maths!$G$3 -> 42 | C8: =Maths!$H$3 -> 0 | D8: =Maths!$I$3 -> 33 | E8: =C8/B8*100 -> 0 | R8: =R7+5 -> 46296 | T8: 99
A9: REASONING | B9: =Reasoning!$G$3 -> 52 | C9: =Reasoning!$H$3 -> 0 | D9: =Reasoning!$I$3 -> 52 | E9: =C9/B9*100 -> 0
A10: GS | B10: =GS!$G$3 -> 63 | C10: =GS!$H$3 -> 0 | D10: =GS!$I$3 -> 63 | E10: =C10/B10*100 -> 0
A11: English | B11: ='English '!G3 -> 19 | C11: ='English '!H3 -> 0 | D11: ='English '!I3 -> 19 | E11: =C11/B11 -> 0
A12: TOTAL | B12: =B11+B10+B9+B8 -> 176 | C12: =C11+C10+C9+C8 -> 0 | D12: =D11+D10+D9+D8 -> 167 | E12: =100-E13 -> 100
A13: Completion% | C13: =C12/B12*100 -> 0 | D13: =D12/B12*100 -> 94.886364 | E13: =C12/B12*100 -> 0
N19: Syllabus
R22: WEAK AREAS
O23: subject wise progess
R24: Subject | S24: Topic | T24: Status | U24: Subject | V24: Topic | W24: Status | X24: Subject | Y24: Topic | Z24: Status
R25: Maths | S25: Geometry | T25: Weak | U25: Reasoning | V25: Blood Relation | W25: Weak | X25: GS | Y25: Current Affair | Z25: Weak
R26: Maths | S26: Algebra | T26: Weak | U26: Reasoning | V26: Cube & Dice | W26: Weak | X26: GS | Y26: Polity&Articles | Z26: Weak
R27: Maths | S27: Mensuration-2D | T27: Weak | U27: Reasoning | V27: Calendar | W27: Weak | X27: English | Y27: Error Detection | Z27: Weak
R28: Maths | S28: Mensuration-3D | T28: Weak | U28: Reasoning | V28: Clock | W28: Weak | X28: English | Y28: Vocabulary | Z28: Weak
R29: Maths | S29: Trigonometry | T29: Weak | U29: GS | V29: History | W29: Weak | X29: English | Y29: Comprehension | Z29: Weak

Sheet MAP
A1: S.No. | B1: States | C1: Capital | D1: Major Cities
A2: 1 | B2: Andhra Pradesh | C2: Amaravati | D2: Visakhapatnam, Vijayawada, Guntur
A3: 2 | B3: Arunachal Pradesh | C3: Itanagar | D3: Tawang, Pasighat
A4: 3 | B4: Assam | C4: Dispur | D4: Guwahati, Dibrugarh, Silchar
A5: 4 | B5: Bihar | C5: Patna | D5: Gaya, Muzaffarpur, Bhagalpur | V5: North → UP, Punjab, Haryana, HP, Uttarakhand
A6: 5 | B6: Chhattisgarh | C6: Raipur | D6: Bhilai, Bilaspur, Durg | V6: South → TN, Kerala, Karnataka, AP, Telangana
A7: 6 | B7: Goa | C7: Panaji | D7: Vasco da Gama, Margao | V7: West → Gujarat, Rajasthan, Maharashtra, Goa
A8: 7 | B8: Gujarat | C8: Gandhinagar | D8: Ahmedabad, Surat, Vadodara | V8: East → Bihar, Jharkhand, Odisha, WB
A9: 8 | B9: Haryana | C9: Chandigarh | D9: Gurugram, Faridabad, Panipat | V9: North-East → 7 sisters + Sikkim
A10: 9 | B10: Himachal Pradesh | C10: Shimla | D10: Manali, Dharamshala
A11: 10 | B11: Jharkhand | C11: Ranchi | D11: Jamshedpur, Dhanbad
A12: 11 | B12: Karnataka | C12: Bengaluru | D12: Mysuru, Mangaluru, Hubli
A13: 12 | B13: Kerala | C13: Thiruvananthapuram | D13: Kochi, Kozhikode
A14: 13 | B14: Madhya Pradesh | C14: Bhopal | D14: Indore, Gwalior, Jabalpur
A15: 14 | B15: Maharashtra | C15: Mumbai | D15: Pune, Nagpur, Nashik | V15: N
A16: 15 | B16: Manipur | C16: Imphal | D16: Thoubal
A17: 16 | B17: Meghalaya | C17: Shillong | D17: Tura
A18: 17 | B18: Mizoram | C18: Aizawl | D18: Lunglei
A19: 18 | B19: Nagaland | C19: Kohima | D19: Dimapur
A20: 19 | B20: Odisha | C20: Bhubaneswar | D20: Cuttack, Rourkela | T20: E | X20: w
A21: 20 | B21: Punjab | C21: Chandigarh | D21: Amritsar, Ludhiana, Jalandhar
A22: 21 | B22: Rajasthan | C22: Jaipur | D22: Jodhpur, Udaipur, Kota
A23: 22 | B23: Sikkim | C23: Gangtok | D23: Namchi
A24: 23 | B24: Tamil Nadu | C24: Chennai | D24: Coimbatore, Madurai, Salem
A25: 24 | B25: Telangana | C25: Hyderabad | D25: Warangal, Nizamabad | V25: S
A26: 25 | B26: Tripura | C26: Agartala | D26: Udaipur
A27: 26 | B27: Uttar Pradesh | C27: Lucknow | D27: Kanpur, Varanasi, Agra
A28: 27 | B28: Uttarakhand | C28: Dehradun | D28: Haridwar, Nainital
A29: 28 | B29: West Bengal | C29: Kolkata | D29: Howrah, Durgapur, Siliguri
A30: 29 | B30: Andaman and Nicobar Islands(UT) | C30: Port Blair | D30: Car Nicobar
A31: 30 | B31: Chandigarh(UT) | C31: Chandigarh | D31: -
A32: 31 | B32: Dadra and Nagar Haveli and Daman and Diu(UT) | C32: Daman | D32: Silvassa, Diu
A33: 32 | B33: Delhi (NCT)(UT) | C33: New Delhi | D33: North Delhi, South Delhi
A34: 33 | B34: Jammu and Kashmir(UT) | C34: Srinagar (Summer), Jammu (Winter) | D34: Anantnag, Baramulla
A35: 34 | B35: Ladakh(UT) | C35: Leh | D35: Kargil
A36: 35 | B36: Lakshadweep(UT) | C36: Kavaratti | D36: Agatti
A37: 36 | B37: Puducherry(UT) | C37: Puducherry | D37: Karaikal, Mahe, Yanam

Sheet Sub
A1: INDEX
A4: GS | E4: Reasoning | I4: GS | M4: English
A5: S.NO. | B5: Topics | E5: S.NO. | F5: Reasoning Topic | I5: S.No | J5: GS Topic | M5: S.No | N5: English Topic
A6: 1 | B6: Number System | D6: TRUE | E6: 1 | F6: =Reasoning!B3 -> Analogy | H6: TRUE | I6: HISTORY | M6: 1 | N6: ='English '!B3 -> Grammar | P6: FALSE
A7: 2 | B7: Simplification | D7: TRUE | E7: 2 | F7: =Reasoning!B7 -> Classification | H7: TRUE | I7: 1 | J7: =GS!B3 -> Ancient History | L7: FALSE | M7: 2 | N7: ='English '!B14 -> Vocabulary | P7: FALSE
A8: 3 | B8: Algebra | D8: TRUE | E8: 3 | F8: =Reasoning!B11 -> Series | H8: TRUE | I8: 2 | J8: =GS!B8 -> Medieval History | L8: FALSE | M8: 3 | N8: ='English '!B18 -> Comprehension | P8: FALSE
A9: 4 | B9: Percentage | D9: TRUE | E9: 4 | F9: =Reasoning!B15 -> Coding-Decoding | H9: FALSE | I9: 3 | J9: =GS!B11 -> Modern History | L9: FALSE | M9: 4 | N9: ='English '!B19 -> Error Detection | P9: FALSE
A10: 5 | B10: Profit and Loss | D10: TRUE | E10: 5 | F10: =Reasoning!B19 -> Blood Relation | H10: FALSE | I10: GEOGRAPHY | M10: 5 | N10: ='English '!B20 -> Sentence Improvement | P10: FALSE
A11: 6 | B11: Discount | D11: FALSE | E11: 6 | F11: =Reasoning!B22 -> Direction & Distance | H11: FALSE | I11: 1 | J11: =GS!B16 -> Physical Geography | M11: 6 | N11: ='English '!B21 -> Cloze Test | P11: FALSE
A12: 7 | B12: Simple Interest | D12: TRUE | E12: 7 | F12: =Reasoning!B25 -> Syllogism | H12: FALSE | I12: 2 | J12: =GS!B20 -> Indian Geography
A13: 8 | B13: Compound Interest | D13: TRUE | E13: 8 | F13: =Reasoning!B28 -> Statement Based | H13: FALSE | I13: 3 | J13: =GS!B24 -> World Geography | L13: FALSE
A14: 9 | B14: Ratio and Proportion | D14: TRUE | E14: 9 | F14: =Reasoning!B31 -> Seating Arrangement | H14: FALSE | I14: polity
A15: 10 | B15: Partnership | D15: FALSE | E15: 10 | F15: =Reasoning!B34 -> Puzzle | H15: FALSE | I15: 1 | J15: =GS!B25 -> Constitution | L15: FALSE
A16: 11 | B16: Average | D16: FALSE | E16: 11 | F16: =Reasoning!B37 -> Ranking & Order | H16: FALSE | I16: 2 | J16: =GS!B30 -> Central Government | L16: FALSE
A17: 12 | B17: Mixture and Alligation | D17: FALSE | E17: 12 | F17: =Reasoning!B39 -> Inequality | H17: FALSE | I17: 3 | J17: =GS!B33 -> Judiciary | L17: FALSE
A18: 13 | B18: Time and Work | D18: FALSE | E18: 13 | F18: =Reasoning!B41 -> Mathematical Operations | H18: FALSE | I18: 4 | J18: =GS!B35 -> Miscellaneous | L18: FALSE
A19: 14 | B19: Pipes and Cisterns | D19: FALSE | E19: =Reasoning!B43 -> Non-Verbal | I19: ECONOMICS
A20: 15 | B20: Time Speed Distance | D20: FALSE | E20: 1 | F20: =Reasoning!C43 -> Mirror Image | H20: FALSE | I20: 1 | J20: =GS!B37 -> Basic Concepts | L20: FALSE
A21: 16 | B21: Boats and Streams | D21: FALSE | E21: 2 | F21: =Reasoning!C44 -> Water Image | H21: FALSE | I21: 2 | J21: =GS!B38 -> National Income | L21: FALSE
A22: 17 | B22: Geometry | D22: FALSE | E22: 3 | F22: =Reasoning!C45 -> Paper Folding | H22: FALSE | I22: 3 | J22: =GS!B39 -> Inflation | L22: FALSE
A23: 18 | B23: Mensuration (2D) | D23: FALSE | E23: 4 | F23: =Reasoning!C46 -> Embedded Figure | H23: FALSE | I23: 4 | J23: =GS!B40 -> Banking | L23: FALSE
A24: 19 | B24: Mensuration (3D) | D24: FALSE | E24: 5 | F24: =Reasoning!C47 -> Figure Series | H24: FALSE | I24: 5 | J24: =GS!B42 -> Public Finance | L24: FALSE
A25: 20 | B25: Trigonometry | D25: FALSE | E25: 6 | F25: =Reasoning!C48 -> Figure Counting | H25: FALSE | I25: 6 | J25: =GS!B43 -> Development | L25: FALSE
A26: 21 | B26: Heights and Distances | D26: FALSE | E26: 7 | F26: =Reasoning!C49 -> Cube & Dice | H26: FALSE | I26: PHYSICS
A27: 22 | B27: Data Interpretation | D27: FALSE | E27: 8 | F27: =Reasoning!B50 -> Calendar | H27: FALSE | I27: 1 | J27: =GS!B44 -> Mechanics | L27: FALSE
A28: 23 | B28: Statistics | D28: FALSE | E28: 9 | F28: =Reasoning!B51 -> Clock | H28: FALSE | I28: 2 | J28: =GS!B46 -> Thermodynamics | L28: FALSE
D29: FALSE | E29: 10 | F29: =Reasoning!B52 -> Venn Diagram | H29: FALSE | I29: 3 | J29: =GS!B47 -> Optics | L29: FALSE
D30: FALSE | E30: 11 | F30: =Reasoning!B54 -> Logical Sequence | H30: FALSE | I30: 4 | J30: =GS!B48 -> Acoustics | L30: FALSE
D31: FALSE | H31: FALSE | J31: =GS!B49 -> Electricity
D32: FALSE | H32: FALSE | I32: Chemistry
I33: 1 | J33: =GS!B50 -> General Chemistry
I34: 2 | J34: =GS!B51 -> Inorganic
I35: 3 | J35: =GS!B52 -> Chemical Reactions
I36: 4 | J36: =GS!B53 -> Acids & Bases
I37: 5 | J37: =GS!B54 -> Metals
I38: Biology
I39: 1 | J39: =GS!B55 -> Cell Biology
I40: 2 | J40: =GS!B56 -> Human Physiology
I41: 3 | J41: =GS!B58 -> Botany
I42: 4 | J42: =GS!B59 -> Nutrition
...

Sheet Mind Map
A1: 1. History (VERY IMPORTANT) | H1: 🏛️ HISTORY | O1: Day | P1: Subject | R1: (PYQ Analysis) | X1: 🥉 3. Polity (2–4 questions)
O2: Mon | P2: History
A3: 🔹 Ancient History (Class 6) | H3: 📘 Class 6 (Ancient) | O3: Tue | P3: Geography | R3: 🏛️ HISTORY (High Weight) | X3: 👉 Mostly repeated
O4: Wed | P4: Polity
A5: What, Where, How and When | H5: Ch 2 → From Hunting to Growing Food | O5: Thu | P5: Science | R5: 🔥 Most Important: | X5: Constitution basics
A6: Indus Valley Civilization | H6: Ch 3 → Earliest Cities | O6: Fri | P6: History + Revision | X6: Fundamental Rights & Duties
A7: Vedic Culture | H7: Ch 4 → What Books & Burials Tell Us | O7: Sat | P7: Geography + Polity | R7: Modern History (Freedom struggle) ⭐⭐⭐ | X7: President, PM, Parliament
A8: Janapadas & Mahajanapadas | H8: Ch 5 → Kingdoms, Kings & Early Republic | O8: Sun | P8: Full Revision + Mock | R8: Revolt of 1857 | X8: Amendments (basic)
A9: Buddhism & Jainism | H9: Ch 6 → New Questions & Ideas (Buddhism/Jainism) | R9: Gandhian movements
A10: Mauryan Empire | H10: Ch 7 → Ashoka | R10: Important Congress sessions
A11: Ashoka | R11: Viceroys & Acts
X12: 🏛️ 4. History (0–3 questions but important)
R13: 👉 Skip deep ancient details (low return)
H14: 📘 Class 7 (Medieval) | X14: 👉 Focus only selected topics
A15: 🔹 Medieval History (Class 7)
H16: Ch 1 → Tracing Changes Through Time | X16: 🔹 Ancient (VERY IMPORTANT)
A17: Delhi Sultanate | H17: Ch 2 → New Kings & Kingdoms | R17: 🌍 GEOGRAPHY
A18: Mughal Empire | H18: Ch 4 → Mughals (VERY IMPORTANT) | X18: Indus Valley Civilization
A19: Akbar’s policies | H19: Ch 6 → Towns, Traders & Craftspersons | R19: 🔥 Most Asked: | X19: Vedic Age
A20: Administration system | H20: Ch 8 → Devotional Paths (Bhakti/Sufi) | X20: Buddhism & Jainism
A21: Bhakti & Sufi Movement | R21: Rivers of India | X21: Maurya (especially Ashoka)
R22: Climate
R23: Soil types | X23: 🔹 Modern (MORE IMPORTANT)
H24: 📘 Class 8 (Modern) | R24: National parks
A25: 🔹 Modern History (Class 8) | R25: Agriculture | X25: Freedom struggle
H26: 👉 DO ALL chapters but focus more on: | X26: Gandhi, INC sessions
A27: British Expansion in India | R27: 👉 Maps & locations = important | X27: Revolts (1857)
A28: Revolt of 1857 | H28: Ch 1 → British Rule
A29: Freedom Struggle | H29: Ch 5 → Revolt of 1857
A30: Indian National Congress | H30: Ch 7 → Tribal & Peasant movements
A31: Gandhian Era | H31: Ch 8 → Freedom struggle | R31: 🏛️ POLITY (MOST SCORING) | X31: 🌍 5. Geography (0–2 questions)
A32: Important movements & leaders | H32: Ch 9–10 → Gandhian Era
R33: 🔥 Top Topics: | X33: 👉 Only basics
R35: Fundamental Rights ⭐⭐⭐ | X35: Rivers, mountains
A36: 🌍 2. Geography | H36: 🌍 GEOGRAPHY | R36: DPSP | X36: Indian states & crops
R37: President vs PM powers | X37: Climate
A38: 🔹 Physical Geography (Class 6–8) | H38: 📘 Class 6–8 (Basics) | R38: Parliament | X38: Soil
R39: Amendments
A40: Earth structure | H40: Earth & Globe
A41: Latitude & Longitude | H41: Motions of Earth | R41: 👉 Direct questions come → easy marks
...

Sheet Weitage
A1: GS | C1: maths | E1: Reasoning | G1: English
A2: Topic | B2: Questions | C2: Topic | D2: Questions | E2: Topic | F2: Questions | G2: Topic | H2: Questions
A3: Current Affairs | B3: 5–7 | C3: Simplification | D3: 2–3 | E3: Analogy | F3: 2–3 | G3: Reading Comprehension | H3: 5
A4: Static GK | B4: 3–5 | C4: Percentage | D4: 2–3 | E4: Classification | F4: 1–2 | G4: Error Detection | H4: 2–3
A5: Polity | B5: 2–4 | C5: Ratio & Proportion | D5: 1–2 | E5: Series (Number/Alphabet) | F5: 2–3 | G5: Fill in the blanks | H5: 2–3
A6: Science | B6: 2–3 | C6: Profit & Loss | D6: 1–2 | E6: Coding-Decoding | F6: 2–3 | G6: Synonyms/Antonyms | H6: 2–3
A7: History | B7: 1–3 | C7: Simple & Compound Interest | D7: 1–2 | E7: Blood Relation | F7: 1–2 | G7: One word substitution | H7: 1–2
A8: Geography | B8: 1–2 | C8: Time & Work | D8: 1–2 | E8: Direction | F8: 1–2 | G8: Idioms & Phrases | H8: 2–3
A9: Economy | B9: 1–2 | C9: Time, Speed & Distance | D9: 1–2 | E9: Puzzle (easy) | F9: 2–3 | G9: Active/Passive | H9: 1–2
C10: Average | D10: 1 | E10: Syllogism | F10: 1–2 | G10: Direct/Indirect | H10: 1–2
C11: Mensuration | D11: 2–3 | E11: Venn Diagram | F11: 1–2 | G11: Cloze Test | H11: 3–5
C12: Algebra (basic) | D12: 1–2 | E12: Mirror/Image | F12: 1
A13: Focus: Current + Science + Polity | E13: Focus: Series + Coding + Puzzle | G13: Focus: RC + Grammar basics + Vocabulary
C14: Focus: Percentage + Ratio + DI + Mensuration

Sheet Maths
A1: Maths | F1: SSC EXAM
A2: Subject | B2: Chapter | C2: Topic | D2: STATUS | E2: STATUS | F2: Sub | G2: Total Topic | H2: Complete | I2: Pending
A3: Maths | B3: Number System | C3: LCM and HCF | D3: FALSE | F3: Maths | G3: =COUNTA(C3:C44) -> 42 | H3: =COUNTIF(D3:D44,TRUE) -> 0 | I3: =COUNTIF(D3:D44,FALSE) -> 33
A4: Maths | B4: Number System | C4: Divisibility Rules | D4: FALSE
A5: Maths | B5: Number System | C5: Remainder Theorem | D5: FALSE
A6: Maths | B6: Number System | C6: Unit Digit | D6: FALSE
A7: Maths | B7: Number System | C7: Surds and Indices | D7: FALSE
A8: Maths | B8: Simplification | C8: BODMAS | D8: FALSE
A9: Maths | B9: Simplification | C9: Fractions | D9: FALSE
A10: Maths | B10: Simplification | C10: Decimals | D10: FALSE
A11: Maths | B11: Simplification | C11: Square Root and Cube Root | D11: FALSE
A12: Maths | B12: Algebra | C12: Linear Equations | D12: FALSE
A13: Maths | B13: Algebra | C13: Quadratic Equations | D13: FALSE
A14: Maths | B14: Algebra | C14: Identities | D14: FALSE
A15: Maths | B15: Algebra | C15: Polynomials | D15: FALSE
... A21: Maths | B21: Arithmetic | C21: Ratio and Proportion | D21: FALSE
A22: Maths | B22: Arithmetic | C22: Partnership | D22: FALSE | F22: n
A23: Maths | B23: Arithmetic | C23: Average | D23: FALSE
A24: Maths | B24: Arithmetic | C24: Mixture and Alligation | D24: FALSE
A25: Maths | B25: Arithmetic | C25: Time and Work | D25: FALSE
A26: Maths | B26: Arithmetic | C26: Pipes and Cisterns | D26: FALSE
A27: Maths | B27: Arithmetic | C27: Time Speed Distance | D27: FALSE
A28: Maths | B28: Arithmetic | C28: Boats and Streams | D28: FALSE
A29: Maths | B29: Geometry | C29: Lines and Angles | D29: FALSE
A30: Maths | B30: Geometry | C30: Triangle | D30: FALSE
A31: Maths | B31: Geometry | C31: Quadrilateral | D31: FALSE
A32: Maths | B32: Geometry | C32: Polygon | D32: FALSE
A33: Maths | B33: Geometry | C33: Circle | D33: FALSE
A34: Maths | B34: Mensuration | C34: 2D Mensuration | D34: FALSE
A35: Maths | B35: Mensuration | C35: 3D Mensuration
A36: Maths | B36: Trigonometry | C36: Trigonometric Ratios
A37: Maths | B37: Trigonometry | C37: Trigonometric Identities
A38: Maths | B38: Trigonometry | C38: Heights and Distances
A39: Maths | B39: Data Interpretation | C39: Bar Graph
A40: Maths | B40: Data Interpretation | C40: Pie Chart
A41: Maths | B41: Data Interpretation | C41: Line Graph
A42: Maths | B42: Data Interpretation | C42: Table | D42: FALSE
A43: Maths | B43: Statistics | C43: Mean Median Mode
A44: Maths | B44: Statistics | C44: Data Analysis

Sheet Reasoning
A1: Reasoning | F1: =Maths!F1 -> SSC EXAM
A2: Subject | B2: Chapter | C2: Topic | D2: Status | E2: Status | F2: Sub | G2: Topic | H2: Complete | I2: Pending
A3: Reasoning | B3: Analogy | C3: Word Analogy | D3: FALSE | F3: Reasoning | G3: =COUNTA(C3:C54) -> 52 | H3: =COUNTIF(D3:D54,TRUE) -> 0 | I3: =COUNTIF(D3:D54,FALSE) -> 52
A4: Reasoning | B4: Analogy | C4: Number Analogy | D4: FALSE
A5: Reasoning | B5: Analogy | C5: Alphabet Analogy | D5: FALSE
A6: Reasoning | B6: Analogy | C6: Mixed Analogy | D6: FALSE
A7: Reasoning | B7: Classification | C7: Word Classification | D7: FALSE
A8: Reasoning | B8: Classification | C8: Number Classification | D8: FALSE
A9: Reasoning | B9: Classification | C9: Alphabet Classification | D9: FALSE
A10: Reasoning | B10: Classification | C10: Figure Classification | D10: FALSE
A11: Reasoning | B11: Series | C11: Number Series | D11: FALSE
A12: Reasoning | B12: Series | C12: Alphabet Series | D12: FALSE
A13: Reasoning | B13: Series | C13: Alphanumeric Series | D13: FALSE
A14: Reasoning | B14: Series | C14: Missing Term | D14: FALSE
A15: Reasoning | B15: Coding-Decoding | C15: Letter Coding | D15: FALSE
... A54: Reasoning | B54: Logical Sequence | C54: Word Arrangement | D54: FALSE

Sheet GS
A1: GS | F1: =Reasoning!F1 -> SSC EXAM
A2: Subject | B2: Chapter | C2: Topic | D2: Status | E2: Status | F2: Sub | G2: Topic | H2: complete | I2: pending
A3: History | B3: Ancient History | C3: Indus Valley Civilization | D3: FALSE | F3: GS | G3: =COUNTA(C3:C65) -> 63 | H3: =COUNTIF(D3:D65,TRUE) -> 0 | I3: =COUNTIF(D3:D65,FALSE) -> 63
A4: History | B4: Ancient History | C4: Vedic Period | D4: FALSE
A5: History | B5: Ancient History | C5: Buddhism & Jainism | D5: FALSE
A6: History | B6: Ancient History | C6: Mauryan Empire | D6: FALSE
A7: History | B7: Ancient History | C7: Gupta Empire | D7: FALSE
A8: History | B8: Medieval History | C8: Delhi Sultanate | D8: FALSE
A9: History | B9: Medieval History | C9: Mughal Empire | D9: FALSE
A10: History | B10: Medieval History | C10: Bhakti & Sufi Movement | D10: FALSE
A11: History | B11: Modern History | C11: Advent of Europeans | D11: FALSE
A12: History | B12: Modern History | C12: Revolt of 1857 | D12: FALSE
A13: History | B13: Modern History | C13: Indian National Movement | D13: FALSE
A14: History | B14: Modern History | C14: Governor Generals & Viceroys | D14: FALSE
A15: History | B15: Modern History | C15: Important Congress Sessions | D15: FALSE
... A65: Current Affairs | B65: Books | C65: Books & Authors | D65: FALSE

Sheet English 
A1: English | F1: =GS!F1 -> SSC EXAM
A2: Subject | B2: Chapter | C2: Topic | D2: Status | E2: Status | F2: Sub | G2: Topic | H2: Complete | I2: Pending
A3: English | B3: Grammar | C3: Noun | D3: FALSE | F3: English | G3: =COUNTA(C3:C21) -> 19 | H3: =COUNTIF(D3:D21,TRUE) -> 0 | I3: =COUNTIF(D3:D21,FALSE) -> 19
A4: English | B4: Grammar | C4: Pronoun | D4: FALSE
A5: English | B5: Grammar | C5: Verb | D5: FALSE
A6: English | B6: Grammar | C6: Tense | D6: FALSE
A7: English | B7: Grammar | C7: Adjective | D7: FALSE
A8: English | B8: Grammar | C8: Adverb | D8: FALSE
A9: English | B9: Grammar | C9: Preposition | D9: FALSE
A10: English | B10: Grammar | C10: Conjunction | D10: FALSE
A11: English | B11: Grammar | C11: Articles | D11: FALSE
A12: English | B12: Grammar | C12: Voice | D12: FALSE
A13: English | B13: Grammar | C13: Narration | D13: FALSE
A14: English | B14: Vocabulary | C14: Synonyms | D14: FALSE
A15: English | B15: Vocabulary | C15: Antonyms | D15: FALSE
... A21: English | B21: Cloze Test | C21: Fill in the Blanks | D21: FALSE
